[2024-11-04 11:02:15,914 ] werkzeug - INFO - [31m[1mWARNING: This is a development server. Do not use it in a production deployment. Use a production WSGI server instead.[0m
 * Running on all addresses (0.0.0.0)
 * Running on http://127.0.0.1:5000
 * Running on http://192.168.222.98:5000
[2024-11-04 11:02:15,915 ] werkzeug - INFO - [33mPress CTRL+C to quit[0m
[2024-11-04 11:02:31,501 ] werkzeug - INFO - 127.0.0.1 - - [04/Nov/2024 11:02:31] "GET / HTTP/1.1" 200 -
[2024-11-04 11:02:32,991 ] werkzeug - INFO - 127.0.0.1 - - [04/Nov/2024 11:02:32] "GET / HTTP/1.1" 200 -
[2024-11-04 11:02:33,611 ] werkzeug - INFO - 127.0.0.1 - - [04/Nov/2024 11:02:33] "[33mGET /style.css HTTP/1.1[0m" 404 -
[2024-11-04 11:03:14,209 ] root - INFO - Entered the load_object method of utils
[2024-11-04 11:03:14,301 ] root - INFO - Exited the load_object method of utils
[2024-11-04 11:03:14,302 ] root - INFO - Entered the load_object method of utils
[2024-11-04 11:03:14,349 ] root - INFO - Exited the load_object method of utils
[2024-11-04 11:03:14,353 ] app - ERROR - Exception on /predictdata [POST]
Traceback (most recent call last):
  File "C:\Users\HP\Documents\Python Projects\Real-Estate-MLOPs-Project\real_estate\pipeline\prediction_pipeline.py", line 39, in predict
    preds = model.predict(data_scaled)
            ^^^^^^^^^^^^^^^^^^^^^^^^^^
  File "C:\Users\HP\anaconda3\envs\realEstate\Lib\site-packages\xgboost\sklearn.py", line 1186, in predict
    predts = self.get_booster().inplace_predict(
             ^^^^^^^^^^^^^^^^^^^^^^^^^^^^^^^^^^^
  File "C:\Users\HP\anaconda3\envs\realEstate\Lib\site-packages\xgboost\core.py", line 2520, in inplace_predict
    raise ValueError(
ValueError: Feature shape mismatch, expected: 8, got 10

During handling of the above exception, another exception occurred:

Traceback (most recent call last):
  File "C:\Users\HP\anaconda3\envs\realEstate\Lib\site-packages\flask\app.py", line 1473, in wsgi_app
    response = self.full_dispatch_request()
               ^^^^^^^^^^^^^^^^^^^^^^^^^^^^
  File "C:\Users\HP\anaconda3\envs\realEstate\Lib\site-packages\flask\app.py", line 882, in full_dispatch_request
    rv = self.handle_user_exception(e)
         ^^^^^^^^^^^^^^^^^^^^^^^^^^^^^
  File "C:\Users\HP\anaconda3\envs\realEstate\Lib\site-packages\flask\app.py", line 880, in full_dispatch_request
    rv = self.dispatch_request()
         ^^^^^^^^^^^^^^^^^^^^^^^
  File "C:\Users\HP\anaconda3\envs\realEstate\Lib\site-packages\flask\app.py", line 865, in dispatch_request
    return self.ensure_sync(self.view_functions[rule.endpoint])(**view_args)  # type: ignore[no-any-return]
           ^^^^^^^^^^^^^^^^^^^^^^^^^^^^^^^^^^^^^^^^^^^^^^^^^^^^^^^^^^^^^^^^^
  File "C:\Users\HP\Documents\Python Projects\Real-Estate-MLOPs-Project\app.py", line 42, in predict_datapoint
    results = predict_pipeline.predict(pred_df)
              ^^^^^^^^^^^^^^^^^^^^^^^^^^^^^^^^^
  File "C:\Users\HP\Documents\Python Projects\Real-Estate-MLOPs-Project\real_estate\pipeline\prediction_pipeline.py", line 43, in predict
    raise realEstateException(e, sys)
real_estate.exception.realEstateException: Error occurred python script name [C:\Users\HP\Documents\Python Projects\Real-Estate-MLOPs-Project\real_estate\pipeline\prediction_pipeline.py] line number [39] error message [Feature shape mismatch, expected: 8, got 10]
[2024-11-04 11:03:14,409 ] werkzeug - INFO - 127.0.0.1 - - [04/Nov/2024 11:03:14] "[35m[1mPOST /predictdata HTTP/1.1[0m" 500 -
